<?xml version="1.0" encoding="UTF-8"?>
<sdf version='1.9'>
  <model name='x500'>
    <pose>0 0 .24 0 0 0</pose>
    <self_collide>false</self_collide>
    <static>false</static>
    <link name="base_link">
      <inertial>
        <mass>2.0</mass>
        <inertia>
          <ixx>0.02166666666666667</ixx>
          <ixy>0</ixy>
          <ixz>0</ixz>
          <iyy>0.02166666666666667</iyy> 
          <iyz>0</iyz>
          <izz>0.04000000000000001</izz>
        </inertia>
      </inertial>
      <gravity>true</gravity>
      <velocity_decay>
        <linear>0.0</linear>
        <angular>0.0</angular>
      </velocity_decay>
      <visual name="base_link_visual">
        <pose>0 0 .025 0 0 3.141592654</pose>
        <geometry>
          <mesh>
            <scale>1 1 1</scale>
            <uri>model://x500/meshes/NXP-HGD-CF.dae</uri>
          </mesh>
        </geometry>
      </visual>
      <visual name="5010_motor_base_0">
        <pose>0.174 -0.174 .032 0 0 -.45</pose>
        <geometry>
          <mesh>
            <scale>1 1 1</scale>
            <uri>model://x500/meshes/5010Base.dae</uri>
          </mesh>
        </geometry>
      </visual>
      <visual name="5010_motor_base_1">
        <pose>-0.174 0.174 .032 0 0 -.45</pose>
        <geometry>
          <mesh>
            <scale>1 1 1</scale> 
            <uri>model://x500/meshes/5010Base.dae</uri>
          </mesh>
        </geometry>
      </visual>
      <visual name="5010_motor_base_2">
        <pose>0.174 0.174 .032 0 0 -.45</pose>
        <geometry>
          <mesh>
            <scale>1 1 1</scale>
            <uri>model://x500/meshes/5010Base.dae</uri>
          </mesh>
        </geometry>
      </visual>
      <visual name="5010_motor_base_3">
        <pose>-0.174 -0.174 .032 0 0 -.45</pose>
        <geometry>
          <mesh>
            <scale>1 1 1</scale>
            <uri>model://x500/meshes/5010Base.dae</uri>
          </mesh>
        </geometry>
      </visual>
      <visual name="NXP_FMUK66_FRONT">
        <pose>0.047 .001 .043 1 0 1.57</pose>
        <cast_shadows>false</cast_shadows>
        <geometry>
          <plane>
            <normal>0 0 1</normal>
            <size>.013 .007</size>
          </plane>
        </geometry>
        <material>
          <diffuse>1.0 1.0 1.0</diffuse>
          <specular>1.0 1.0 1.0</specular>
          <pbr>
            <metal>
              <albedo_map>model://x500/materials/textures/nxp.png</albedo_map>
            </metal>
          </pbr>
        </material>
      </visual>
      <visual name="NXP_FMUK66_TOP">
        <pose>-0.023 0 .0515 0 0 -1.57</pose>
        <cast_shadows>false</cast_shadows>
        <geometry>
          <plane>
            <normal>0 0 1</normal>
            <size>.013 .007</size>
          </plane>
        </geometry>
        <material>
          <diffuse>1.0 1.0 1.0</diffuse>
          <specular>1.0 1.0 1.0</specular>
          <pbr>
            <metal>
              <albedo_map>model://x500/materials/textures/nxp.png</albedo_map>
            </metal>
          </pbr>
        </material>
      </visual>
      <visual name="RDDRONE_FMUK66_TOP">
        <pose>-.03 0 .0515 0 0 -1.57</pose>
        <cast_shadows>false</cast_shadows>
        <geometry>
          <plane>
            <normal>0 0 1</normal>
            <size>.032 .0034</size>
          </plane>
        </geometry>
        <material>
          <diffuse>1.0 1.0 1.0</diffuse>
          <specular>1.0 1.0 1.0</specular>
          <pbr>
            <metal>
              <albedo_map>model://x500/materials/textures/rd.png</albedo_map>
            </metal>
          </pbr>
        </material>
      </visual>
      <collision name="base_link_collision_0">
        <pose>0 0 .007 0 0 0</pose>
        <geometry>
          <box>
            <size>0.35355339059327373 0.35355339059327373 0.05</size>
          </box>
        </geometry>
        <surface>
          <contact>
            <ode>
              <min_depth>0.001</min_depth>
              <max_vel>100.0</max_vel>
            </ode>
          </contact>
          <friction>
            <ode>
              <mu>100000.0</mu>
              <mu2>100000.0</mu2>
            </ode>
          </friction>
        </surface>
      </collision>
      <collision name="base_link_collision_1">
        <pose>0 -0.098 -.123 -0.35 0 0</pose>
        <geometry>
          <box>
            <size>0.015 0.015 0.21</size>
          </box>
        </geometry>
        <surface>
          <contact>
            <ode>
              <min_depth>0.001</min_depth>
              <max_vel>0</max_vel>
            </ode>
          </contact>
          <friction> 
            <ode/>
          </friction>
        </surface>
      </collision>
      <collision name="base_link_collision_2">
        <pose>0 0.098 -.123 0.35 0 0</pose>
        <geometry>
          <box>
            <size>0.015 0.015 0.21</size>
          </box>
        </geometry>
        <surface>
          <contact>
            <ode>
              <min_depth>0.001</min_depth>
              <max_vel>0</max_vel>
            </ode>
          </contact>
          <friction>
            <ode/>
          </friction>
        </surface>
      </collision>
      <collision name="base_link_collision_3">
        <pose>0 -0.132 -.2195 0 0 0</pose>
        <geometry>
          <box>
            <size>0.25 0.015 0.015</size>
          </box>
        </geometry>
        <surface>
          <contact>
            <ode>
              <min_depth>0.001</min_depth>
              <max_vel>0</max_vel>
            </ode>
          </contact>
          <friction>
            <ode/>
          </friction>
        </surface>
      </collision>
      <collision name="base_link_collision_4">
        <pose>0 0.132 -.2195 0 0 0</pose>
        <geometry>
          <box>
            <size>0.25 0.015 0.015</size>
          </box>
        </geometry>
        <surface>
          <contact>
            <ode>
              <min_depth>0.001</min_depth>
              <max_vel>0</max_vel>
            </ode>
          </contact>
          <friction>
            <ode/>
          </friction>
        </surface>
      </collision>
      <sensor name="air_pressure_sensor" type="air_pressure">
        <always_on>1</always_on>
        <update_rate>50</update_rate>
        <air_pressure>
          <pressure>
            <noise type="gaussian">
              <mean>0</mean>
              <stddev>0.01</stddev>
            </noise> 
          </pressure>
        </air_pressure>
      </sensor>
    </link>

    <!-- ========================  GIMBAL INTEGRADO  ======================== -->
    <link name="gimbal_base_link">
      <!-- <pose degrees="true">0.22 -0.005 -0.05 90 0 90</pose>  -->
      <pose relative_to="base_link">0.12 -0.005 -0.05 1.5708 0 1.5708</pose>
      <inertial>
        <mass>0.2</mass>
        <inertia>
          <ixx>0.0001</ixx>
          <ixy>0</ixy>
          <ixz>0</ixz>
          <iyy>0.0001</iyy>
          <iyz>0</iyz>
          <izz>0.0001</izz>
        </inertia>
      </inertial>
      <visual name="gimbal_base_visual">
        <geometry>
          <mesh>
            <uri>model://gimbal_small_3d/meshes/base_plate.dae</uri>
            <scale>0.5 0.5 0.5</scale>
          </mesh>
        </geometry>
        <material>
          <ambient>0.1 0.1 0.1</ambient>
          <diffuse>0.1 0.1 0.1</diffuse>
          <specular>0.01 0.01 0.01 1.0</specular>
        </material>
      </visual>
      <collision name="gimbal_base_collision">
        <!-- <pose>0.01 0.075 -0.025 0 0 0</pose> -->
        <geometry>
          <box>
            <size>0.05 0.025 0.075</size>
          </box>
        </geometry>
      </collision>
    </link>
    <joint name="gimbal_joint" type="revolute">
      <parent>base_link</parent>
      <child>gimbal_base_link</child>
      <axis>
        <xyz>0 0 1</xyz>
        <limit>
          <lower>0</lower>
          <upper>0</upper>
        </limit>
      </axis>
    </joint>

    <link name="yaw_link">
      <!-- <pose relative_to="gimbal_base_link">0.0105 0.065 -0.002 0 0 0</pose> -->
      <pose relative_to="gimbal_base_link">0.0 0.0 0.0 0 0 0</pose>
      <inertial>
        <mass>0.01</mass>
        <inertia>
          <ixx>0.00001</ixx>
          <ixy>0</ixy>
          <ixz>0</ixz>
          <iyy>0.00001</iyy>
          <iyz>0</iyz>
          <izz>0.00001</izz>
        </inertia>
      </inertial>
      <visual name="yaw_visual">
        <geometry>
          <mesh>
            <uri>model://gimbal_small_3d/meshes/yaw_arm.dae</uri>
            <scale>0.5 0.5 0.5</scale>
          </mesh>
        </geometry>
        <material>
          <ambient>0.1 0.1 0.1</ambient>
          <diffuse>0.1 0.1 0.1</diffuse>
          <specular>0.01 0.01 0.01 1.0</specular>
        </material>
      </visual>
      <collision name="yaw_collision">
        <geometry>
          <mesh>
            <uri>model://gimbal_small_3d/meshes/yaw_arm.dae</uri>
            <scale>0.5 0.5 0.5</scale>
          </mesh>
        </geometry>
      </collision>
    </link>
    <joint name="yaw_joint" type="revolute">
      <parent>gimbal_base_link</parent>
      <child>yaw_link</child>
      <axis>
        <xyz>0 1 0</xyz>
        <dynamics>
          <damping>0.01</damping>
        </dynamics>
        <limit>
          <lower>-3.1415926</lower>
          <upper>3.1415926</upper>
        </limit>
      </axis>
      <pose>0.0105 0.065 -0.002 0 0 0</pose>
    </joint>

    <link name="roll_link">
      <!-- <pose relative_to="yaw_link">0.0099 0.002 -0.05 0 0 0</pose> -->
      <pose relative_to="yaw_link">0.0 0.0 0.0 0 0 0</pose>
      <inertial>
        <mass>0.01</mass>
        <inertia>
          <ixx>0.00001</ixx>
          <ixy>0</ixy>
          <ixz>0</ixz>
          <iyy>0.00001</iyy>
          <iyz>0</iyz>
          <izz>0.00001</izz>
        </inertia>
      </inertial>
      <visual name="roll_visual">
        <geometry>
          <mesh>
            <uri>model://gimbal_small_3d/meshes/roll_arm.dae</uri>
            <scale>0.5 0.5 0.5</scale>
          </mesh>
        </geometry>
        <material>
          <ambient>0.1 0.1 0.1</ambient>
          <diffuse>0.1 0.1 0.1</diffuse>
          <specular>0.01 0.01 0.01 1.0</specular>
        </material>
      </visual>
      <collision name="roll_collision">
        <geometry>
          <mesh>
            <uri>model://gimbal_small_3d/meshes/roll_arm.dae</uri>
            <scale>0.5 0.5 0.5</scale>
          </mesh>
        </geometry>
      </collision>
    </link>
    <joint name="roll_joint" type="revolute">
      <parent>yaw_link</parent>
      <child>roll_link</child>
      <axis> 
        <xyz>0 0 1</xyz>
        <dynamics>
          <damping>0.01</damping>
        </dynamics>
        <limit>
          <lower>-3.1415926</lower>
          <upper>3.1415926</upper>
        </limit>
      </axis>
      <pose>0.0099 0.002 -0.05 0 0 0</pose>
    </joint>

    <link name="pitch_link">
      <!-- <pose relative_to="roll_link">0.045 0.0021 0.0199 0 0 0</pose> -->
      <pose relative_to="roll_link">0.0 0.0 0.0 0 0 0</pose>
      <inertial>
        <mass>0.01</mass>
        <inertia>
          <ixx>0.00001</ixx>
          <ixy>0</ixy>
          <ixz>0</ixz>
          <iyy>0.00001</iyy>
          <iyz>0</iyz>
          <izz>0.00001</izz>
        </inertia>
      </inertial>
      <visual name="pitch_visual">
         
        <geometry>
          <mesh>
            <uri>model://gimbal_small_3d/meshes/camera_enclosure.dae</uri>
            <scale>0.5 0.5 0.5</scale>
          </mesh>
        </geometry>
        <material>
          <ambient>0.4 0.4 0.4</ambient>
          <diffuse>0.4 0.4 0.4</diffuse>
          <specular>0.1 0.1 0.1 1.0</specular>
        </material>
      </visual>
      <collision name="pitch_collision">
        <!-- <pose>0 0 0 0 0 0</pose> -->
        <geometry>
          <mesh>
            <uri>model://gimbal_small_3d/meshes/camera_enclosure.dae</uri>
            <scale>0.5 0.5 0.5</scale>
          </mesh>
        </geometry>
      </collision>
      <visual name="camera_visual">
        <pose>0 0 0.02 0 0 0</pose>
        <geometry>
          <cylinder>
            <radius>0.025</radius>
            <length>0.050</length>
          </cylinder>
        </geometry>
        <material>
          <ambient>0.4 0.4 0.4</ambient>
          <diffuse>0.4 0.4 0.4</diffuse>
          <specular>0.1 0.1 0.1 1.0</specular>
        </material>
      </visual>
      <collision name="camera_collision">
        <pose>0 0 0.02 0 0 0</pose>
        <geometry>
          <cylinder>
            <radius>0.025</radius>
            <length>0.050</length>
          </cylinder>
        </geometry>
      </collision>
      <sensor name="camera" type="camera">
        <pose>0 0 0.1 -1.57 -1.57 0</pose>
        <camera>
          <camera_info_topic>camera/camera_info</camera_info_topic>
          <horizontal_fov>1.089</horizontal_fov>
          <image>
            <format>R8G8B8</format>
            <width>640</width>
            <height>480</height>
          </image>
          <clip>
            <near>0.01</near>
            <far>100</far>
          </clip> 
        </camera>
        <always_on>1</always_on>
        <update_rate>30</update_rate>
        <visualize>1</visualize>
        <topic>/camera/image</topic>
         
        <!-- <plugin filename="CameraZoomPlugin"
            name="CameraZoomPlugin">
          <max_zoom>125.0</max_zoom>
          <slew_rate>0.42514285714</slew_rate>
        </plugin>
        
        <plugin name="GstCameraPlugin"
            filename="GstCameraPlugin">
          <udp_host>127.0.0.1</udp_host>
          <udp_port>5600</udp_port>
          <use_basic_pipeline>true</use_basic_pipeline>
          <use_cuda>false</use_cuda>
        </plugin> -->

      </sensor>
    </link>
    <joint name="pitch_joint" type="revolute">
      <parent>roll_link</parent>
      <child>pitch_link</child>
      <axis>
        <xyz>1 0 0</xyz>
        <dynamics>
          <damping>0.01</damping>
        </dynamics>
        <limit>
          <lower>-3.1415926</lower>
          <upper>3.1415926</upper>
        </limit>
      </axis>
      <pose>0.045 0.0021 0.0199 0 0 0</pose>
    </joint>

      
    <!-- <include>
      <uri>model://gimbal_small_3d</uri>
      <name>gimbal</name>
      <pose degrees="true">0.12 -0.005 -0.05 90 0 90</pose> 
       
    </include> -->

    <!-- Gimbal Joint -->
    <!-- <joint name="gimbal_joint" type="revolute">
      <parent>base_link</parent>
      <child>gimbal::base_link</child>
      <axis>
        <xyz>0 0 1</xyz>
        <limit>
          <lower>0</lower>
          <upper>0</upper>
        </limit>
      </axis>
    </joint> --> 

    <!-- ========================  MOTORES / OTROS LINKS  ===================== -->

    <link name='imu_link'>
      <inertial>
        <pose>0 0 0 0 0 0</pose>
        <mass>0.15</mass>
        <inertia>
          <ixx>0.00001</ixx>
          <ixy>0</ixy>
          <ixz>0</ixz>
          <iyy>0.00002</iyy>
          <iyz>0</iyz>
          <izz>0.00002</izz>
        </inertia>
      </inertial>
      <sensor name="imu_sensor" type="imu">
        <pose>0 0 0 3.141593 0 0</pose>
        <always_on>1</always_on>
        <update_rate>1000.0</update_rate>
      </sensor>
    </link>
    <joint name='iris/imu_joint' type='fixed'>
      <child>imu_link</child>
      <parent>base_link</parent>
      <axis>
        <xyz>0 0 1</xyz>
        <limit>
          <lower>0</lower>
          <upper>0</upper>
          <effort>0</effort>
          <velocity>0</velocity>
        </limit>
        <dynamics>
          <damping>1.0</damping>
        </dynamics>
        <use_parent_model_frame>1</use_parent_model_frame>
      </axis>
      <physics>
        <ode>
          <implicit_spring_damper>1</implicit_spring_damper>
        </ode>
      </physics>
    </joint>
    
    <link name="rotor_0">
      <gravity>true</gravity>
      <self_collide>false</self_collide>
      <velocity_decay/>
      <pose>0.174 -0.174 0.06 0 0 0</pose>
      <inertial>
          <mass>0.016076923076923075</mass>
          <inertia>
            <ixx>3.8464910483993325e-07</ixx>
            <iyy>2.6115851691700804e-05</iyy>
            <izz>2.649858234714004e-05</izz>
          </inertia>
        </inertial>
      <visual name="rotor_0_visual">
        <pose>-0.022 -0.14638461538461536 -0.016 0 0 0</pose>
        <geometry>
          <mesh>
            <scale>0.8461538461538461 0.8461538461538461 0.8461538461538461</scale>
            <uri>model://x500/meshes/1345_prop_ccw.stl</uri>
          </mesh>
        </geometry>
        <material>
          <script>
            <name>Gazebo/DarkGrey</name>
            <uri>file://media/materials/scripts/gazebo.material</uri>
          </script>
        </material>
      </visual>
      <visual name="rotor_0_visual_motor_bell">
        <pose>0 0 -.032 0 0 0</pose>
        <geometry>
          <mesh>
            <scale>1 1 1</scale>
            <uri>model://x500/meshes/5010Bell.dae</uri>
          </mesh>
        </geometry>
      </visual>
      <collision name="rotor_0_collision">
        <pose>0 0 0 0 0 0 </pose>
        <geometry>
          <cylinder>
            <radius>0.1</radius>  <!-- Usar cilindro en lugar de caja -->
            <length>0.005</length>
          </cylinder>
        </geometry>
        <surface>
          <contact>
            <ode>
              <min_depth>0.001</min_depth>
              <max_vel>0</max_vel>
            </ode>
          </contact>
          <friction>
            <ode/>
          </friction>
        </surface>
      </collision>
    </link>
    <joint name="rotor_0_joint" type="revolute">
      <parent>base_link</parent>
      <child>rotor_0</child>
      <axis>
        <xyz>0 0 1</xyz>
        <limit>
          <lower>-1e+16</lower>
          <upper>1e+16</upper>
        </limit>
        <dynamics>
          <damping>0.004</damping>
          <spring_reference>0</spring_reference>
          <spring_stiffness>0</spring_stiffness>
        </dynamics>
        <use_parent_model_frame>1</use_parent_model_frame>
      </axis>
      <physics>
        <ode>
          <implicit_spring_damper>1</implicit_spring_damper>
        </ode>
      </physics>
    </joint>


    <link name="rotor_1">
      <gravity>true</gravity>
      <self_collide>false</self_collide>
      <velocity_decay/>
      <pose>-0.174 0.174 0.06 0 0 0</pose>
      <inertial>
          <mass>0.016076923076923075</mass>
          <inertia>
            <ixx>3.8464910483993325e-07</ixx>
            <iyy>2.6115851691700804e-05</iyy>
            <izz>2.649858234714004e-05</izz>
          </inertia>
        </inertial>
      <visual name="rotor_1_visual">
        <pose>-0.022 -0.14638461538461536 -0.016 0 0 0</pose>
        <geometry>
          <mesh>
            <scale>0.8461538461538461 0.8461538461538461 0.8461538461538461</scale>
            <uri>model://x500/meshes/1345_prop_ccw.stl</uri>
          </mesh>
        </geometry>
        <material>
          <script>
            <name>Gazebo/DarkGrey</name>
            <uri>file://media/materials/scripts/gazebo.material</uri>
          </script>
        </material>
      </visual>
      <visual name="rotor_1_visual_motor_top">
        <pose>0 0 -.032 0 0 0</pose>
        <geometry>
          <mesh>
            <scale>1 1 1</scale>
            <uri>model://x500/meshes/5010Bell.dae</uri>
          </mesh>
        </geometry>
      </visual>
      <collision name="rotor_1_collision">
        <pose>0 0 0 0 0 0 </pose>
        <geometry>
          <cylinder>
            <radius>0.1</radius>  <!-- Usar cilindro en lugar de caja -->
            <length>0.005</length>
          </cylinder>
        </geometry>
        <surface>
          <contact>
            <ode>
              <min_depth>0.001</min_depth>
              <max_vel>0</max_vel>
            </ode>
          </contact>
          <friction>
            <ode/>
          </friction>
        </surface>
      </collision>
    </link>
    <joint name="rotor_1_joint" type="revolute">
      <parent>base_link</parent>
      <child>rotor_1</child>
      <axis>
        <xyz>0 0 1</xyz>
        <limit>
          <lower>-1e+16</lower>
          <upper>1e+16</upper>
        </limit>
        <dynamics>
          <damping>0.004</damping>
          <spring_reference>0</spring_reference>
          <spring_stiffness>0</spring_stiffness>
        </dynamics>
        <use_parent_model_frame>1</use_parent_model_frame>
      </axis>
      <physics>
        <ode>
          <implicit_spring_damper>1</implicit_spring_damper>
        </ode>
      </physics>
    </joint>

    
    <link name="rotor_2">
      <gravity>true</gravity>
      <self_collide>false</self_collide>
      <velocity_decay/>
      <pose>0.174 0.174 0.06 0 0 0</pose>
      <inertial>
        <pose>0 0 0 0 -0 0</pose>
        <mass>0.016076923076923075</mass>
        <inertia>
          <ixx>3.8464910483993325e-07</ixx>
          <iyy>2.6115851691700804e-05</iyy>
          <izz>2.649858234714004e-05</izz>
        </inertia>
      </inertial>
      <visual name="rotor_2_visual">
        <pose>-0.022 -0.14638461538461536 -0.016 0 0 0</pose>
        <geometry>
          <mesh>
            <scale>0.8461538461538461 0.8461538461538461 0.8461538461538461</scale>
            <uri>model://x500/meshes/1345_prop_cw.stl</uri>
          </mesh>
        </geometry>
        <material>
          <script>
            <name>Gazebo/DarkGrey</name>
            <uri>file://media/materials/scripts/gazebo.material</uri>
          </script>
        </material>
      </visual>
      <visual name="rotor_2_visual_motor_top">
        <pose>0 0 -.032 0 0 0</pose>
        <geometry>
          <mesh>
            <scale>1 1 1</scale>
            <uri>model://x500/meshes/5010Bell.dae</uri>
          </mesh>
        </geometry>
      </visual>
      <collision name="rotor_2_collision">
        <pose>0 0 0 0 0 0 </pose>
        <geometry>
          <cylinder>
            <radius>0.1</radius>  <!-- Usar cilindro en lugar de caja -->
            <length>0.005</length>
          </cylinder>
        </geometry>
        <surface>
          <contact>
            <ode>
              <min_depth>0.001</min_depth>
              <max_vel>0</max_vel>
            </ode>
          </contact>
          <friction>
            <ode/>
          </friction>
        </surface>
      </collision>
    </link>
    <joint name="rotor_2_joint" type="revolute">
      <parent>base_link</parent>
      <child>rotor_2</child>
      <axis>
        <xyz>0 0 1</xyz>
        <limit>
          <lower>-1e+16</lower>
          <upper>1e+16</upper>
        </limit>
        <dynamics>
          <damping>0.004</damping>
          <spring_reference>0</spring_reference>
          <spring_stiffness>0</spring_stiffness>
        </dynamics>
        <use_parent_model_frame>1</use_parent_model_frame>
      </axis>
      <physics>
        <ode>
          <implicit_spring_damper>1</implicit_spring_damper>
        </ode>
      </physics>
    </joint>
    <link name="rotor_3">
      <gravity>true</gravity>
      <self_collide>false</self_collide>
      <velocity_decay/>
      <pose>-0.174 -0.174 0.06 0 0 0</pose>
      <inertial>
          <mass>0.016076923076923075</mass>
          <inertia>
            <ixx>3.8464910483993325e-07</ixx>
            <iyy>2.6115851691700804e-05</iyy>
            <izz>2.649858234714004e-05</izz>
          </inertia>
        </inertial>
      <visual name="rotor_3_visual">
        <pose>-0.022 -0.14638461538461536 -0.016 0 0 0</pose>
        <geometry>
          <mesh>
            <scale>0.8461538461538461 0.8461538461538461 0.8461538461538461</scale>
            <uri>model://x500/meshes/1345_prop_cw.stl</uri>
          </mesh>
        </geometry>
        <material>
          <script>
            <name>Gazebo/DarkGrey</name>
            <uri>file://media/materials/scripts/gazebo.material</uri>
          </script>
        </material>
      </visual>
      <visual name="rotor_3_visual_motor_top">
        <pose>0 0 -.032 0 0 0</pose>
        <geometry>
          <mesh>
            <scale>1 1 1</scale>
            <uri>model://x500/meshes/5010Bell.dae</uri>
          </mesh>
        </geometry>
      </visual>
      <collision name="rotor_3_collision">
        <pose>0 0 0 0 0 0 </pose>
        <geometry>
          <cylinder>
            <radius>0.1</radius>  <!-- Usar cilindro en lugar de caja -->
            <length>0.005</length>
          </cylinder>
        </geometry>
        <surface>
          <contact>
            <ode>
              <min_depth>0.001</min_depth>
              <max_vel>0</max_vel>
            </ode>
          </contact>
          <friction>
            <ode/>
          </friction>
        </surface>
      </collision>
    </link>
    <joint name="rotor_3_joint" type="revolute">
      <parent>base_link</parent>
      <child>rotor_3</child>
      <axis>
        <xyz>0 0 1</xyz>
        <limit>
          <lower>-1e+16</lower>
          <upper>1e+16</upper>
        </limit>
        <dynamics>
          <damping>0.004</damping>
          <spring_reference>0</spring_reference>
          <spring_stiffness>0</spring_stiffness>
        </dynamics>
        <use_parent_model_frame>1</use_parent_model_frame>
      </axis>
      <physics>
        <ode>
          <implicit_spring_damper>1</implicit_spring_damper>
        </ode>
      </physics>
    </joint>
    <!-- Plugins -->
   
    <!-- ################# -->
    <!-- FISICAS REALISTAS -->
    <!-- ################# -->

    <!-- Estado de articulaciones -->
    <plugin filename="libignition-gazebo-joint-state-publisher-system.so"
      name="ignition::gazebo::systems::JointStatePublisher">
    </plugin>

    <!-- Lift & Drag (Aerodinámica) -->
    <!-- Repetir para cada rotor ajustando "cp" (posición) -->

    <!-- Ejemplo rotor 0 CCW -->
    <plugin filename="libignition-gazebo-lift-drag-system.so"
        name="ignition::gazebo::systems::LiftDrag">
      <a0>0.3</a0>
      <alpha_stall>1.4</alpha_stall>
      <cla>4.2500</cla>
      <cda>0.10</cda>
      <cma>0.0</cma>
      <cla_stall>-0.025</cla_stall>
      <cda_stall>0.0</cda_stall>
      <cma_stall>0.0</cma_stall>
      <area>0.002</area>
      <air_density>1.2041</air_density>
      <cp>0.174 -0.174 0.06</cp> 
      <forward>0 1 0</forward>
      <upward>0 0 1</upward>
      <link_name>rotor_0</link_name>
    </plugin>

    <!-- Ejemplo rotor 1 CW -->
    <plugin filename="libignition-gazebo-lift-drag-system.so"
        name="ignition::gazebo::systems::LiftDrag">
      <a0>0.3</a0>
      <alpha_stall>1.4</alpha_stall>
      <cla>4.2500</cla>
      <cda>0.10</cda>
      <cma>0.0</cma>
      <cla_stall>-0.025</cla_stall>
      <cda_stall>0.0</cda_stall>
      <cma_stall>0.0</cma_stall>
      <area>0.002</area>
      <air_density>1.2041</air_density>
      <cp>-0.174 0.174 0.06</cp> 
      <forward>0 -1 0</forward>
      <upward>0 0 1</upward>
      <link_name>rotor_1</link_name>
    </plugin>

    <!-- Lift & Drag Rotor 2 -->
    <plugin filename="libignition-gazebo-lift-drag-system.so"
        name="ignition::gazebo::systems::LiftDrag">
      <a0>0.3</a0>
      <alpha_stall>1.4</alpha_stall>
      <cla>4.2500</cla>
      <cda>0.10</cda>
      <cma>0.0</cma>
      <cla_stall>-0.025</cla_stall>
      <cda_stall>0.0</cda_stall>
      <cma_stall>0.0</cma_stall>
      <area>0.002</area>
      <air_density>1.2041</air_density>
      <cp>0.174 0.174 0.06</cp> 
      <forward>0 -1 0</forward>
      <upward>0 0 1</upward>
      <link_name>rotor_2</link_name>
    </plugin>

    <!-- Lift & Drag Rotor 3 -->
    <plugin filename="libignition-gazebo-lift-drag-system.so"
        name="ignition::gazebo::systems::LiftDrag">
      <a0>0.3</a0>
      <alpha_stall>1.4</alpha_stall>
      <cla>4.2500</cla>
      <cda>0.10</cda>
      <cma>0.0</cma>
      <cla_stall>-0.025</cla_stall>
      <cda_stall>0.0</cda_stall>
      <cma_stall>0.0</cma_stall>
      <area>0.002</area>
      <air_density>1.2041</air_density>
      <cp>-0.174 -0.174 0.06</cp> 
      <forward>0 1 0</forward>
      <upward>0 0 1</upward>
      <link_name>rotor_3</link_name>
    </plugin>

    <plugin filename="libignition-gazebo-apply-joint-force-system.so"
      name="ignition::gazebo::systems::ApplyJointForce">
      <joint_name>rotor_0_joint</joint_name>
    </plugin>
    <plugin filename="libignition-gazebo-apply-joint-force-system.so"
      name="ignition::gazebo::systems::ApplyJointForce">
      <joint_name>rotor_1_joint</joint_name>
    </plugin>
    <plugin filename="libignition-gazebo-apply-joint-force-system.so"
      name="ignition::gazebo::systems::ApplyJointForce">
      <joint_name>rotor_2_joint</joint_name>
    </plugin>
    <plugin filename="libignition-gazebo-apply-joint-force-system.so"
      name="ignition::gazebo::systems::ApplyJointForce">
      <joint_name>rotor_3_joint</joint_name>
    </plugin>


    <!-- ################ -->
    <!-- ARDUPILOT PLUGIN -->
    <!-- ################ -->

    <plugin name="ArduPilotPlugin" filename="libArduPilotPlugin.so">
      <!-- Dirección IP y puerto para comunicación -->
      <fdm_addr>127.0.0.1</fdm_addr>
      <fdm_port_in>9002</fdm_port_in>
      <connectionTimeoutMaxCount>5</connectionTimeoutMaxCount>
      <lock_step>1</lock_step>

      <!-- Conversión de coordenadas -->
      <modelXYZToAirplaneXForwardZDown degrees="true">0 0 0 180 0 0</modelXYZToAirplaneXForwardZDown>
      <gazeboXYZToNED degrees="true">0 0 0 180 0 90</gazeboXYZToNED>

      <!-- Sensor IMU -->
      <!-- <imuName>base_link::imu_sensor</imuName> -->
      <imuName>imu_sensor</imuName>

      <!-- Configuración de los motores -->
      <control channel="0">
        <jointName>rotor_0_joint</jointName>
        <useForce>1</useForce>
        <multiplier>838</multiplier>
        <offset>0</offset>
        <servo_min>1100</servo_min>
        <servo_max>1900</servo_max>
        <deadband>50</deadband>
        <type>VELOCITY</type>
        <p_gain>0.05</p_gain>
        <i_gain>0</i_gain>
        <d_gain>0</d_gain>
        <i_max>0</i_max>
        <i_min>0</i_min>
        <cmd_max>2.5</cmd_max>
        <cmd_min>-2.5</cmd_min>
        <controlVelocitySlowdownSim>1</controlVelocitySlowdownSim>
      </control>

      <control channel="1">
        <jointName>rotor_1_joint</jointName>
        <useForce>1</useForce>
        <multiplier>838</multiplier>
        <offset>0</offset>
        <servo_min>1100</servo_min>
        <servo_max>1900</servo_max>
        <deadband>50</deadband>
        <type>VELOCITY</type>
        <p_gain>0.05</p_gain>
        <i_gain>0</i_gain>
        <d_gain>0</d_gain>
        <i_max>0</i_max>
        <i_min>0</i_min>
        <cmd_max>2.5</cmd_max>
        <cmd_min>-2.5</cmd_min>
        <controlVelocitySlowdownSim>1</controlVelocitySlowdownSim>
      </control>

      <control channel="2">
        <jointName>rotor_2_joint</jointName>
        <useForce>1</useForce>
        <multiplier>-838</multiplier>
        <offset>0</offset>
        <servo_min>1100</servo_min>
        <servo_max>1900</servo_max>
        <deadband>50</deadband>
        <type>VELOCITY</type>
        <p_gain>0.05</p_gain>
        <i_gain>0</i_gain>
        <d_gain>0</d_gain>
        <i_max>0</i_max>
        <i_min>0</i_min>
        <cmd_max>2.5</cmd_max>
        <cmd_min>-2.5</cmd_min>
        <controlVelocitySlowdownSim>1</controlVelocitySlowdownSim>
      </control>

      <control channel="3">
        <jointName>rotor_3_joint</jointName>
        <useForce>1</useForce>
        <multiplier>-838</multiplier>
        <offset>0</offset>
        <servo_min>1100</servo_min>
        <servo_max>1900</servo_max> 
        <deadband>50</deadband>
        <type>VELOCITY</type>
        <p_gain>0.05</p_gain>
        <i_gain>0</i_gain>
        <d_gain>0</d_gain>
        <i_max>0</i_max>
        <i_min>0</i_min>
        <cmd_max>2.5</cmd_max>
        <cmd_min>-2.5</cmd_min>
        <controlVelocitySlowdownSim>1</controlVelocitySlowdownSim>
      </control>

      <!-- Gimbal control -->
      <!-- En realidad es 10 -->
      <control channel="9">
        <jointName>roll_joint</jointName>
        <multiplier>1.047197551196</multiplier>
        <offset>-0.5236</offset>
        <servo_min>1100</servo_min>
        <servo_max>1900</servo_max> 
        <type>POSITION</type>
        <cmd_topic>/gimbal/cmd_roll</cmd_topic> 
        <p_gain>2</p_gain>
        <controlVelocitySlowdownSim>1</controlVelocitySlowdownSim>
      </control>

      <!-- En realidad es 11 -->
      <control channel="10">
        <jointName>pitch_joint</jointName>
        <multiplier>2.047197551196</multiplier>
        <offset>-0.5236</offset>
        <servo_min>1100</servo_min>
        <servo_max>1900</servo_max>
        <!-- <type>COMMAND</type> -->
        <type>POSITION</type>
        <cmd_topic>/gimbal/cmd_pitch</cmd_topic>
        <p_gain>2</p_gain>
        <controlVelocitySlowdownSim>1</controlVelocitySlowdownSim>
      </control>

      <!-- En realidad es 12 -->
      <control channel="11">
        <jointName>yaw_joint</jointName>
        <multiplier>1.047197551196</multiplier>
        <offset>-0.5236</offset>
        <servo_min>1100</servo_min>
        <servo_max>1900</servo_max>
        <!-- <type>COMMAND</type> -->
        <type>POSITION</type>
        <cmd_topic>/gimbal/cmd_yaw</cmd_topic>
        <p_gain>2</p_gain>
        <controlVelocitySlowdownSim>1</controlVelocitySlowdownSim>
      </control>

    </plugin>

  </model>
</sdf>
