<?xml version='1.0' encoding='utf-8'?>
<robot name="FAST_ASSEMBLY">
    <link name="GIMBAL_RAPIDO-v15_CAMERA_ASSEMBLY">
        <inertial>
            <origin xyz="-0.01 0.0032756026727633627 1.8077881414058085e-11" rpy="0.0 0.0 0.0" />
            <mass value="0.004718154701058241" />
            <inertia ixx="3.0879515170826206e-07" iyy="7.336772213625277e-07" izz="8.37855837638672e-07" ixy="9.559887501325002e-23" iyz="-6.161995284685584e-16" ixz="-9.414691255548289e-23" />
        </inertial>
        <visual name="GIMBAL_RAPIDO-v15_CAMERA_ASSEMBLY_visual">
            <origin xyz="0.0 0.0 0.0" rpy="0.0 0.0 0.0" />
            <geometry>
                <mesh filename="meshes/GIMBAL_RAPIDO-v15_CAMERA_ASSEMBLY.stl" scale="0.001 0.001 0.001" />
            </geometry>
        </visual>
        <collision name="GIMBAL_RAPIDO-v15_CAMERA_ASSEMBLY_collision">
            <origin xyz="0.0 0.0 0.0" rpy="0.0 0.0 0.0" />
            <geometry>
                <mesh filename="meshes/GIMBAL_RAPIDO-v15_CAMERA_ASSEMBLY.stl" scale="0.001 0.001 0.001" />
            </geometry>
        </collision>
    </link>
    <link name="GIMBAL_RAPIDO-v15_PITCH_MOTOR">
        <inertial>
            <origin xyz="-0.009999999990825306 0.010568880302318675 1.6857777396239728e-11" rpy="0.0 0.0 0.0" />
            <mass value="0.007638596904392609" />
            <inertia ixx="1.2557409997488117e-06" iyy="2.048053521892667e-06" izz="2.9916259244081893e-06" ixy="-1.8765547722116055e-16" iyz="-1.5485998442789362e-15" ixz="5.026193091076733e-17" />
        </inertial>
        <visual name="GIMBAL_RAPIDO-v15_PITCH_MOTOR_visual">
            <origin xyz="0.0 0.0 0.0" rpy="0.0 0.0 0.0" />
            <geometry>
                <mesh filename="meshes/GIMBAL_RAPIDO-v15_PITCH_MOTOR.stl" scale="0.001 0.001 0.001" />
            </geometry>
        </visual>
        <collision name="GIMBAL_RAPIDO-v15_PITCH_MOTOR_collision">
            <origin xyz="0.0 0.0 0.0" rpy="0.0 0.0 0.0" />
            <geometry>
                <mesh filename="meshes/GIMBAL_RAPIDO-v15_PITCH_MOTOR.stl" scale="0.001 0.001 0.001" />
            </geometry>
        </collision>
    </link>
    <link name="GIMBAL_RAPIDO-v15_YAW_MOTOR">
        <inertial>
            <origin xyz="-0.010000000000000002 0.011999999999999993 0.028041296060991112" rpy="0.0 0.0 0.0" />
            <mass value="0.001965584567608258" />
            <inertia ixx="5.419222061348012e-08" iyy="5.4192220613481986e-08" izz="9.68140936320338e-08" ixy="-3.8828493331415954e-23" iyz="4.235164736271502e-22" ixz="-8.819066777543582e-23" />
        </inertial>
        <visual name="GIMBAL_RAPIDO-v15_YAW_MOTOR_visual">
            <origin xyz="0.0 0.0 0.0" rpy="0.0 0.0 0.0" />
            <geometry>
                <mesh filename="meshes/GIMBAL_RAPIDO-v15_YAW_MOTOR.stl" scale="0.001 0.001 0.001" />
            </geometry>
        </visual>
        <collision name="GIMBAL_RAPIDO-v15_YAW_MOTOR_collision">
            <origin xyz="0.0 0.0 0.0" rpy="0.0 0.0 0.0" />
            <geometry>
                <mesh filename="meshes/GIMBAL_RAPIDO-v15_YAW_MOTOR.stl" scale="0.001 0.001 0.001" />
            </geometry>
        </collision>
    </link>
    <link name="GIMBAL_RAPIDO-v15_CAMERA">
        <inertial>
            <origin xyz="-0.00999999999988678 -0.0011254136057887352 -4.440892098500626e-18" rpy="0.0 0.0 0.0" />
            <mass value="0.006869216157004747" />
            <inertia ixx="3.9437228490212125e-07" iyy="3.840762745352083e-07" izz="3.9437228879629085e-07" ixy="6.76730574888037e-18" iyz="-1.1529671502421527e-38" ixz="9.414691248488082e-23" />
        </inertial>
        <visual name="GIMBAL_RAPIDO-v15_CAMERA_visual">
            <origin xyz="0.0 0.0 0.0" rpy="0.0 0.0 0.0" />
            <geometry>
                <mesh filename="meshes/GIMBAL_RAPIDO-v15_CAMERA.stl" scale="0.001 0.001 0.001" />
            </geometry>
        </visual>
        <collision name="GIMBAL_RAPIDO-v15_CAMERA_collision">
            <origin xyz="0.0 0.0 0.0" rpy="0.0 0.0 0.0" />
            <geometry>
                <mesh filename="meshes/GIMBAL_RAPIDO-v15_CAMERA.stl" scale="0.001 0.001 0.001" />
            </geometry>
        </collision>
    </link>
    <link name="GIMBAL_RAPIDO-v15_ROLL_MOTOR">
        <inertial>
            <origin xyz="-0.010000000000071346 0.023096726580276183 0.011293638910718804" rpy="0.0 0.0 0.0" />
            <mass value="0.004184733711997446" />
            <inertia ixx="9.423565304118208e-07" iyy="6.376214264668031e-07" izz="4.894283102382267e-07" ixy="1.6130476193766658e-18" iyz="3.7184911209001784e-07" ixz="-3.371966627019227e-18" />
        </inertial>
        <visual name="GIMBAL_RAPIDO-v15_ROLL_MOTOR_visual">
            <origin xyz="0.0 0.0 0.0" rpy="0.0 0.0 0.0" />
            <geometry>
                <mesh filename="meshes/GIMBAL_RAPIDO-v15_ROLL_MOTOR.stl" scale="0.001 0.001 0.001" />
            </geometry>
        </visual>
        <collision name="GIMBAL_RAPIDO-v15_ROLL_MOTOR_collision">
            <origin xyz="0.0 0.0 0.0" rpy="0.0 0.0 0.0" />
            <geometry>
                <mesh filename="meshes/GIMBAL_RAPIDO-v15_ROLL_MOTOR.stl" scale="0.001 0.001 0.001" />
            </geometry>
        </collision>
    </link>
    <link name="FAST_DESING-v7_Componente1">
        <inertial>
            <origin xyz="2.1661863625288823e-17 0.000901779099596209 0.0013886844844376955" rpy="0.0 0.0 0.0" />
            <mass value="0.890102902091786" />
            <inertia ixx="0.0026930074950412336" iyy="0.0013586036951104019" izz="0.0034856635823616445" ixy="4.644896504861607e-18" iyz="0.0001186562592042062" ixz="1.5692786392447297e-18" />
        </inertial>
        <visual name="FAST_DESING-v7_Componente1_visual">
            <origin xyz="0.0 0.0 0.0" rpy="0.0 0.0 0.0" />
            <geometry>
                <mesh filename="meshes/FAST_DESING-v7_Componente1.stl" scale="0.001 0.001 0.001" />
            </geometry>
        </visual>
        <collision name="FAST_DESING-v7_Componente1_collision">
            <origin xyz="0.0 0.0 0.0" rpy="0.0 0.0 0.0" />
            <geometry>
                <mesh filename="meshes/FAST_DESING-v7_Componente1.stl" scale="0.001 0.001 0.001" />
            </geometry>
        </collision>
    </link>
    <joint name="FAST_DESING-v7_Componente1_Rígida-1" type="fixed">
        <origin xyz="0.0 -0.08066288 0.006999999999999999" rpy="3.141592653589793 -0.0 0.0" />
        <parent link="FAST_DESING-v7_Componente1" />
        <child link="GIMBAL_RAPIDO-v15_YAW_MOTOR" />
    </joint>
    <joint name="GIMBAL_RAPIDO-v15_YAW_MOTOR_Revolución-1" type="revolute">
        <origin xyz="-0.009999999999999992 0.012000002692912607 0.025000000000000005" rpy="3.141592653589793 -0.0 0.0" />
        <parent link="GIMBAL_RAPIDO-v15_YAW_MOTOR" />
        <child link="GIMBAL_RAPIDO-v15_ROLL_MOTOR" />
        <axis xyz="0.0 0.0 1.0" />
        <limit lower="-1.570796" upper="1.570796" effort="1000000" velocity="1000000" />
    </joint>
    <joint name="GIMBAL_RAPIDO-v15_ROLL_MOTOR_Revolución-2" type="revolute">
        <origin xyz="-0.009999999999999992 0.028000002692912612 4.440892098500626e-18" rpy="1.5707963267948966 -0.0 0.0" />
        <parent link="GIMBAL_RAPIDO-v15_ROLL_MOTOR" />
        <child link="GIMBAL_RAPIDO-v15_PITCH_MOTOR" />
        <axis xyz="0.0 0.0 1.0" />
        <limit lower="-0.785398" upper="0.785398" effort="1000000" velocity="1000000" />
    </joint>
    <joint name="GIMBAL_RAPIDO-v15_PITCH_MOTOR_Revolución-3" type="revolute">
        <origin xyz="0.005000000000000009 2.6929126129005e-09 4.440892098500626e-18" rpy="-0.0 -1.5707963267948966 0" />
        <parent link="GIMBAL_RAPIDO-v15_PITCH_MOTOR" />
        <child link="GIMBAL_RAPIDO-v15_CAMERA_ASSEMBLY" />
        <axis xyz="0.0 0.0 1.0" />
        <limit lower="-1.570796" upper="1.570796" effort="1000000" velocity="1000000" />
    </joint>
    <joint name="GIMBAL_RAPIDO-v15_CAMERA_ASSEMBLY_Rígida-4" type="fixed">
        <origin xyz="-0.009999999999999992 0.008000002692912603 -0.005999999999999997" rpy="3.141592653589793 -0.0 0.0" />
        <parent link="GIMBAL_RAPIDO-v15_CAMERA_ASSEMBLY" />
        <child link="GIMBAL_RAPIDO-v15_CAMERA" />
    </joint>
</robot>