<sdf version='1.9'>
  <model name='dron_gimbal_proto'>
    <link name='FAST_DESING-v7_Componente1'>
      <inertial>
        <pose>-2.203400968648746e-05 0.0006956186391046669 0.001339262243577077 0 0 0</pose>
        <mass>0.8920684866593942</mass>
        <inertia>
          <ixx>0.00271121789331064</ixx>
          <ixy>-1.835040241796366e-06</ixy>
          <ixz>-4.3990880017759238e-07</ixz>
          <iyy>0.0013598407272736601</iyy>
          <iyz>0.00011454026751183861</iyz>
          <izz>0.0035031260132807589</izz>
        </inertia>
      </inertial>
      <collision name='FAST_DESING-v7_Componente1_collision_collision'>
        <pose>0 0 0 0 0 0</pose>
        <geometry>
          <mesh>
            <scale>0.001 0.001 0.001</scale>
            <uri>meshes/FAST_DESING-v7_Componente1.stl</uri>
          </mesh>
        </geometry>
      </collision>
      <collision name='FAST_DESING-v7_Componente1_fixed_joint_lump__GIMBAL_RAPIDO-v15_YAW_MOTOR_collision_collision_1'>
        <pose>0 -0.08066288000000001 0.006999999999999999 3.141592653589793 0 0</pose>
        <geometry>
          <mesh>
            <scale>0.001 0.001 0.001</scale>
            <uri>meshes/GIMBAL_RAPIDO-v15_YAW_MOTOR.stl</uri>
          </mesh>
        </geometry>
      </collision>
      <visual name='FAST_DESING-v7_Componente1_visual_visual'>
        <pose>0 0 0 0 0 0</pose>
        <geometry>
          <mesh>
            <scale>0.001 0.001 0.001</scale>
            <uri>meshes/FAST_DESING-v7_Componente1.stl</uri>
          </mesh>
        </geometry>
      </visual>
      <visual name='FAST_DESING-v7_Componente1_fixed_joint_lump__GIMBAL_RAPIDO-v15_YAW_MOTOR_visual_visual_1'>
        <pose>0 -0.08066288000000001 0.006999999999999999 3.141592653589793 0 0</pose>
        <geometry>
          <mesh>
            <scale>0.001 0.001 0.001</scale>
            <uri>meshes/GIMBAL_RAPIDO-v15_YAW_MOTOR.stl</uri>
          </mesh>
        </geometry>
      </visual>
    </link>
    <joint name='GIMBAL_RAPIDO-v15_YAW_MOTOR_Revolución-1' type='revolute'>
      <pose relative_to='FAST_DESING-v7_Componente1'>-0.009999999999999992 -0.09266288269291262 -0.01800000000000001 -2.449293598294706e-16 0 0</pose>
      <parent>FAST_DESING-v7_Componente1</parent>
      <child>GIMBAL_RAPIDO-v15_ROLL_MOTOR</child>
      <axis>
        <xyz>0 0 1</xyz>
        <limit>
          <lower>-1.5707960000000001</lower>
          <upper>1.5707960000000001</upper>
          <effort>1000000</effort>
          <velocity>1000000</velocity>
        </limit>
        <dynamics>
          <spring_reference>0</spring_reference>
          <spring_stiffness>0</spring_stiffness>
        </dynamics>
      </axis>
    </joint>
    <link name='GIMBAL_RAPIDO-v15_ROLL_MOTOR'>
      <pose relative_to='GIMBAL_RAPIDO-v15_YAW_MOTOR_Revolución-1'>0 0 0 0 0 0</pose>
      <inertial>
        <pose>-0.01000000000007135 0.02309672658027618 0.0112936389107188 0 0 0</pose>
        <mass>0.0041847337119974458</mass>
        <inertia>
          <ixx>9.4235653041182079e-07</ixx>
          <ixy>1.613047619376666e-18</ixy>
          <ixz>-3.3719666270192272e-18</ixz>
          <iyy>6.3762142646680309e-07</iyy>
          <iyz>3.7184911209001778e-07</iyz>
          <izz>4.8942831023822666e-07</izz>
        </inertia>
      </inertial>
      <collision name='GIMBAL_RAPIDO-v15_ROLL_MOTOR_collision_collision'>
        <pose>0 0 0 0 0 0</pose>
        <geometry>
          <mesh>
            <scale>0.001 0.001 0.001</scale>
            <uri>meshes/GIMBAL_RAPIDO-v15_ROLL_MOTOR.stl</uri>
          </mesh>
        </geometry>
      </collision>
      <visual name='GIMBAL_RAPIDO-v15_ROLL_MOTOR_visual_visual'>
        <pose>0 0 0 0 0 0</pose>
        <geometry>
          <mesh>
            <scale>0.001 0.001 0.001</scale>
            <uri>meshes/GIMBAL_RAPIDO-v15_ROLL_MOTOR.stl</uri>
          </mesh>
        </geometry>
      </visual>
    </link>
    <joint name='GIMBAL_RAPIDO-v15_ROLL_MOTOR_Revolución-2' type='revolute'>
      <pose relative_to='GIMBAL_RAPIDO-v15_ROLL_MOTOR'>-0.009999999999999992 0.02800000269291261 4.440892098500626e-18 1.570796326794896 0 0</pose>
      <parent>GIMBAL_RAPIDO-v15_ROLL_MOTOR</parent>
      <child>GIMBAL_RAPIDO-v15_PITCH_MOTOR</child>
      <axis>
        <xyz>0 0 1</xyz>
        <limit>
          <lower>-0.78539800000000004</lower>
          <upper>0.78539800000000004</upper>
          <effort>1000000</effort>
          <velocity>1000000</velocity>
        </limit>
        <dynamics>
          <spring_reference>0</spring_reference>
          <spring_stiffness>0</spring_stiffness>
        </dynamics>
      </axis>
    </joint>
    <link name='GIMBAL_RAPIDO-v15_PITCH_MOTOR'>
      <pose relative_to='GIMBAL_RAPIDO-v15_ROLL_MOTOR_Revolución-2'>0 0 0 0 0 0</pose>
      <inertial>
        <pose>-0.009999999990825306 0.01056888030231867 1.685777739623973e-11 0 0 0</pose>
        <mass>0.0076385969043926086</mass>
        <inertia>
          <ixx>1.2557409997488119e-06</ixx>
          <ixy>-1.876554772211605e-16</ixy>
          <ixz>5.0261930910767328e-17</ixz>
          <iyy>2.048053521892667e-06</iyy>
          <iyz>-1.548599844278936e-15</iyz>
          <izz>2.9916259244081889e-06</izz>
        </inertia>
      </inertial>
      <collision name='GIMBAL_RAPIDO-v15_PITCH_MOTOR_collision_collision'>
        <pose>0 0 0 0 0 0</pose>
        <geometry>
          <mesh>
            <scale>0.001 0.001 0.001</scale>
            <uri>meshes/GIMBAL_RAPIDO-v15_PITCH_MOTOR.stl</uri>
          </mesh>
        </geometry>
      </collision>
      <visual name='GIMBAL_RAPIDO-v15_PITCH_MOTOR_visual_visual'>
        <pose>0 0 0 0 0 0</pose>
        <geometry>
          <mesh>
            <scale>0.001 0.001 0.001</scale>
            <uri>meshes/GIMBAL_RAPIDO-v15_PITCH_MOTOR.stl</uri>
          </mesh>
        </geometry>
      </visual>
    </link>
    <joint name='GIMBAL_RAPIDO-v15_PITCH_MOTOR_Revolución-3' type='revolute'>
      <pose relative_to='GIMBAL_RAPIDO-v15_PITCH_MOTOR'>0.005000000000000009 2.6929126129005e-09 4.440892098500626e-18 0 -1.570796326794897 0</pose>
      <parent>GIMBAL_RAPIDO-v15_PITCH_MOTOR</parent>
      <child>GIMBAL_RAPIDO-v15_CAMERA_ASSEMBLY</child>
      <axis>
        <xyz>0 0 1</xyz>
        <limit>
          <lower>-1.5707960000000001</lower>
          <upper>1.5707960000000001</upper>
          <effort>1000000</effort>
          <velocity>1000000</velocity>
        </limit>
        <dynamics>
          <spring_reference>0</spring_reference>
          <spring_stiffness>0</spring_stiffness>
        </dynamics>
      </axis>
    </joint>
    <link name='GIMBAL_RAPIDO-v15_CAMERA_ASSEMBLY'>
      <pose relative_to='GIMBAL_RAPIDO-v15_PITCH_MOTOR_Revolución-3'>0 0 0 0 0 0</pose>
      <inertial>
        <pose>-0.01592819220258845 0.006743484625190748 -0.003556915314232376 0 0 0</pose>
        <mass>0.01158737085806299</mass>
        <inertia>
          <ixx>8.9957456892801798e-07</ixx>
          <ixy>1.6362003535698349e-07</ixy>
          <ixz>-1.6782076796215781e-07</ixz>
          <iyy>1.498147236070584e-06</iyy>
          <iyz>9.8172020898952474e-08</iyz>
          <izz>1.607644076761808e-06</izz>
        </inertia>
      </inertial>
      <collision name='GIMBAL_RAPIDO-v15_CAMERA_ASSEMBLY_collision_collision'>
        <pose>0 0 0 0 0 0</pose>
        <geometry>
          <mesh>
            <scale>0.001 0.001 0.001</scale>
            <uri>meshes/GIMBAL_RAPIDO-v15_CAMERA_ASSEMBLY.stl</uri>
          </mesh>
        </geometry>
      </collision>
      <collision name='GIMBAL_RAPIDO-v15_CAMERA_ASSEMBLY_fixed_joint_lump__GIMBAL_RAPIDO-v15_CAMERA_collision_collision_1'>
        <pose>-0.009999999999999992 0.008000002692912603 -0.005999999999999997 3.141592653589793 0 0</pose>
        <geometry>
          <mesh>
            <scale>0.001 0.001 0.001</scale>
            <uri>meshes/GIMBAL_RAPIDO-v15_CAMERA.stl</uri>
          </mesh>
        </geometry>
      </collision>
      <visual name='GIMBAL_RAPIDO-v15_CAMERA_ASSEMBLY_visual_visual'>
        <pose>0 0 0 0 0 0</pose>
        <geometry>
          <mesh>
            <scale>0.001 0.001 0.001</scale>
            <uri>meshes/GIMBAL_RAPIDO-v15_CAMERA_ASSEMBLY.stl</uri>
          </mesh>
        </geometry>
      </visual>
      <visual name='GIMBAL_RAPIDO-v15_CAMERA_ASSEMBLY_fixed_joint_lump__GIMBAL_RAPIDO-v15_CAMERA_visual_visual_1'>
        <pose>-0.009999999999999992 0.008000002692912603 -0.005999999999999997 3.141592653589793 0 0</pose>
        <geometry>
          <mesh>
            <scale>0.001 0.001 0.001</scale>
            <uri>meshes/GIMBAL_RAPIDO-v15_CAMERA.stl</uri>
          </mesh>
        </geometry>
      </visual>
    </link>
    <frame name='FAST_DESING-v7_Componente1_Rígida-1' attached_to='FAST_DESING-v7_Componente1'>
      <pose>0 -0.080663 0.007 3.14159 -0 0</pose>
    </frame>
    <frame name='GIMBAL_RAPIDO-v15_YAW_MOTOR' attached_to='FAST_DESING-v7_Componente1_Rígida-1'/>
    <frame name='GIMBAL_RAPIDO-v15_CAMERA_ASSEMBLY_Rígida-4' attached_to='GIMBAL_RAPIDO-v15_CAMERA_ASSEMBLY'>
      <pose>-0.01 0.008 -0.006 3.14159 -0 0</pose>
    </frame>
    <frame name='GIMBAL_RAPIDO-v15_CAMERA' attached_to='GIMBAL_RAPIDO-v15_CAMERA_ASSEMBLY_Rígida-4'/>
  </model>
</sdf>
